2025-10-31 15:48:02,373 ERROR: Exception on /edit_profile [POST] [in /home/unbud/temp/microblog/venv/lib/python3.10/site-packages/flask/app.py:875]
Traceback (most recent call last):
  File "/home/unbud/temp/microblog/venv/lib/python3.10/site-packages/sqlalchemy/engine/base.py", line 1967, in _exec_single_context
    self.dialect.do_execute(
  File "/home/unbud/temp/microblog/venv/lib/python3.10/site-packages/sqlalchemy/engine/default.py", line 951, in do_execute
    cursor.execute(statement, parameters)
sqlite3.IntegrityError: UNIQUE constraint failed: user.username

The above exception was the direct cause of the following exception:

Traceback (most recent call last):
  File "/home/unbud/temp/microblog/venv/lib/python3.10/site-packages/flask/app.py", line 1511, in wsgi_app
    response = self.full_dispatch_request()
  File "/home/unbud/temp/microblog/venv/lib/python3.10/site-packages/flask/app.py", line 919, in full_dispatch_request
    rv = self.handle_user_exception(e)
  File "/home/unbud/temp/microblog/venv/lib/python3.10/site-packages/flask/app.py", line 917, in full_dispatch_request
    rv = self.dispatch_request()
  File "/home/unbud/temp/microblog/venv/lib/python3.10/site-packages/flask/app.py", line 902, in dispatch_request
    return self.ensure_sync(self.view_functions[rule.endpoint])(**view_args)  # type: ignore[no-any-return]
  File "/home/unbud/temp/microblog/venv/lib/python3.10/site-packages/flask_login/utils.py", line 290, in decorated_view
    return current_app.ensure_sync(func)(*args, **kwargs)
  File "/home/unbud/temp/microblog/app/routes.py", line 81, in edit_profile
    db.session.commit()
  File "/home/unbud/temp/microblog/venv/lib/python3.10/site-packages/sqlalchemy/orm/scoping.py", line 597, in commit
    return self._proxied.commit()
  File "/home/unbud/temp/microblog/venv/lib/python3.10/site-packages/sqlalchemy/orm/session.py", line 2030, in commit
    trans.commit(_to_root=True)
  File "<string>", line 2, in commit
  File "/home/unbud/temp/microblog/venv/lib/python3.10/site-packages/sqlalchemy/orm/state_changes.py", line 137, in _go
    ret_value = fn(self, *arg, **kw)
  File "/home/unbud/temp/microblog/venv/lib/python3.10/site-packages/sqlalchemy/orm/session.py", line 1311, in commit
    self._prepare_impl()
  File "<string>", line 2, in _prepare_impl
  File "/home/unbud/temp/microblog/venv/lib/python3.10/site-packages/sqlalchemy/orm/state_changes.py", line 137, in _go
    ret_value = fn(self, *arg, **kw)
  File "/home/unbud/temp/microblog/venv/lib/python3.10/site-packages/sqlalchemy/orm/session.py", line 1286, in _prepare_impl
    self.session.flush()
  File "/home/unbud/temp/microblog/venv/lib/python3.10/site-packages/sqlalchemy/orm/session.py", line 4331, in flush
    self._flush(objects)
  File "/home/unbud/temp/microblog/venv/lib/python3.10/site-packages/sqlalchemy/orm/session.py", line 4466, in _flush
    with util.safe_reraise():
  File "/home/unbud/temp/microblog/venv/lib/python3.10/site-packages/sqlalchemy/util/langhelpers.py", line 224, in __exit__
    raise exc_value.with_traceback(exc_tb)
  File "/home/unbud/temp/microblog/venv/lib/python3.10/site-packages/sqlalchemy/orm/session.py", line 4427, in _flush
    flush_context.execute()
  File "/home/unbud/temp/microblog/venv/lib/python3.10/site-packages/sqlalchemy/orm/unitofwork.py", line 466, in execute
    rec.execute(self)
  File "/home/unbud/temp/microblog/venv/lib/python3.10/site-packages/sqlalchemy/orm/unitofwork.py", line 642, in execute
    util.preloaded.orm_persistence.save_obj(
  File "/home/unbud/temp/microblog/venv/lib/python3.10/site-packages/sqlalchemy/orm/persistence.py", line 85, in save_obj
    _emit_update_statements(
  File "/home/unbud/temp/microblog/venv/lib/python3.10/site-packages/sqlalchemy/orm/persistence.py", line 912, in _emit_update_statements
    c = connection.execute(
  File "/home/unbud/temp/microblog/venv/lib/python3.10/site-packages/sqlalchemy/engine/base.py", line 1419, in execute
    return meth(
  File "/home/unbud/temp/microblog/venv/lib/python3.10/site-packages/sqlalchemy/sql/elements.py", line 526, in _execute_on_connection
    return connection._execute_clauseelement(
  File "/home/unbud/temp/microblog/venv/lib/python3.10/site-packages/sqlalchemy/engine/base.py", line 1641, in _execute_clauseelement
    ret = self._execute_context(
  File "/home/unbud/temp/microblog/venv/lib/python3.10/site-packages/sqlalchemy/engine/base.py", line 1846, in _execute_context
    return self._exec_single_context(
  File "/home/unbud/temp/microblog/venv/lib/python3.10/site-packages/sqlalchemy/engine/base.py", line 1986, in _exec_single_context
    self._handle_dbapi_exception(
  File "/home/unbud/temp/microblog/venv/lib/python3.10/site-packages/sqlalchemy/engine/base.py", line 2355, in _handle_dbapi_exception
    raise sqlalchemy_exception.with_traceback(exc_info[2]) from e
  File "/home/unbud/temp/microblog/venv/lib/python3.10/site-packages/sqlalchemy/engine/base.py", line 1967, in _exec_single_context
    self.dialect.do_execute(
  File "/home/unbud/temp/microblog/venv/lib/python3.10/site-packages/sqlalchemy/engine/default.py", line 951, in do_execute
    cursor.execute(statement, parameters)
sqlalchemy.exc.IntegrityError: (sqlite3.IntegrityError) UNIQUE constraint failed: user.username
[SQL: UPDATE user SET username=? WHERE user.id = ?]
[parameters: ('mmmaike', 1)]
(Background on this error at: https://sqlalche.me/e/20/gkpj)
2025-10-31 15:52:09,446 INFO: Microblog startup [in /home/unbud/temp/microblog/app/__init__.py:28]
2025-10-31 15:52:21,726 ERROR: Exception on /edit_profile [POST] [in /home/unbud/temp/microblog/venv/lib/python3.10/site-packages/flask/app.py:875]
Traceback (most recent call last):
  File "/home/unbud/temp/microblog/venv/lib/python3.10/site-packages/flask/app.py", line 1511, in wsgi_app
    response = self.full_dispatch_request()
  File "/home/unbud/temp/microblog/venv/lib/python3.10/site-packages/flask/app.py", line 919, in full_dispatch_request
    rv = self.handle_user_exception(e)
  File "/home/unbud/temp/microblog/venv/lib/python3.10/site-packages/flask/app.py", line 917, in full_dispatch_request
    rv = self.dispatch_request()
  File "/home/unbud/temp/microblog/venv/lib/python3.10/site-packages/flask/app.py", line 902, in dispatch_request
    return self.ensure_sync(self.view_functions[rule.endpoint])(**view_args)  # type: ignore[no-any-return]
  File "/home/unbud/temp/microblog/venv/lib/python3.10/site-packages/flask_login/utils.py", line 290, in decorated_view
    return current_app.ensure_sync(func)(*args, **kwargs)
  File "/home/unbud/temp/microblog/app/routes.py", line 78, in edit_profile
    if form.validate_on_submit():
  File "/home/unbud/temp/microblog/venv/lib/python3.10/site-packages/flask_wtf/form.py", line 86, in validate_on_submit
    return self.is_submitted() and self.validate(extra_validators=extra_validators)
  File "/home/unbud/temp/microblog/venv/lib/python3.10/site-packages/wtforms/form.py", line 330, in validate
    return super().validate(extra)
  File "/home/unbud/temp/microblog/venv/lib/python3.10/site-packages/wtforms/form.py", line 147, in validate
    if not field.validate(self, extra):
  File "/home/unbud/temp/microblog/venv/lib/python3.10/site-packages/wtforms/fields/core.py", line 234, in validate
    stop_validation = self._run_validation_chain(form, chain)
  File "/home/unbud/temp/microblog/venv/lib/python3.10/site-packages/wtforms/fields/core.py", line 254, in _run_validation_chain
    validator(form, self)
  File "/home/unbud/temp/microblog/app/forms.py", line 46, in validate_username
    user = db.session.scalar(sa.select(User).where(User.username == username.data))
NameError: name 'db' is not defined
2025-10-31 15:53:25,142 INFO: Microblog startup [in /home/unbud/temp/microblog/app/__init__.py:28]
2025-10-31 15:53:35,949 ERROR: Exception on /edit_profile [POST] [in /home/unbud/temp/microblog/venv/lib/python3.10/site-packages/flask/app.py:875]
Traceback (most recent call last):
  File "/home/unbud/temp/microblog/venv/lib/python3.10/site-packages/flask/app.py", line 1511, in wsgi_app
    response = self.full_dispatch_request()
  File "/home/unbud/temp/microblog/venv/lib/python3.10/site-packages/flask/app.py", line 919, in full_dispatch_request
    rv = self.handle_user_exception(e)
  File "/home/unbud/temp/microblog/venv/lib/python3.10/site-packages/flask/app.py", line 917, in full_dispatch_request
    rv = self.dispatch_request()
  File "/home/unbud/temp/microblog/venv/lib/python3.10/site-packages/flask/app.py", line 902, in dispatch_request
    return self.ensure_sync(self.view_functions[rule.endpoint])(**view_args)  # type: ignore[no-any-return]
  File "/home/unbud/temp/microblog/venv/lib/python3.10/site-packages/flask_login/utils.py", line 290, in decorated_view
    return current_app.ensure_sync(func)(*args, **kwargs)
  File "/home/unbud/temp/microblog/app/routes.py", line 78, in edit_profile
    if form.validate_on_submit():
  File "/home/unbud/temp/microblog/venv/lib/python3.10/site-packages/flask_wtf/form.py", line 86, in validate_on_submit
    return self.is_submitted() and self.validate(extra_validators=extra_validators)
  File "/home/unbud/temp/microblog/venv/lib/python3.10/site-packages/wtforms/form.py", line 330, in validate
    return super().validate(extra)
  File "/home/unbud/temp/microblog/venv/lib/python3.10/site-packages/wtforms/form.py", line 147, in validate
    if not field.validate(self, extra):
  File "/home/unbud/temp/microblog/venv/lib/python3.10/site-packages/wtforms/fields/core.py", line 234, in validate
    stop_validation = self._run_validation_chain(form, chain)
  File "/home/unbud/temp/microblog/venv/lib/python3.10/site-packages/wtforms/fields/core.py", line 254, in _run_validation_chain
    validator(form, self)
  File "/home/unbud/temp/microblog/app/forms.py", line 47, in validate_username
    user = db.session.scalar(sa.select(User).where(User.username == username.data))
NameError: name 'sa' is not defined
2025-10-31 15:54:37,389 INFO: Microblog startup [in /home/unbud/temp/microblog/app/__init__.py:28]
